Watching for file changes with StatReloader
Performing system checks...

System check identified no issues (0 silenced).
March 21, 2023 - 00:03:28
Django version 4.1.7, using settings 'dsam.settings'
Starting development server at http://127.0.0.1:8000/
Quit the server with CONTROL-C.
Watching for file changes with StatReloader
Invalid HTTP_HOST header: '0.0.0.0:8000'. You may need to add '0.0.0.0' to ALLOWED_HOSTS.
Traceback (most recent call last):
  File "/home/cheh/projects/dsam/backend/venv/lib/python3.10/site-packages/django/core/handlers/exception.py", line 56, in inner
    response = get_response(request)
  File "/home/cheh/projects/dsam/backend/venv/lib/python3.10/site-packages/django/utils/deprecation.py", line 135, in __call__
    response = self.process_request(request)
  File "/home/cheh/projects/dsam/backend/venv/lib/python3.10/site-packages/django/middleware/common.py", line 48, in process_request
    host = request.get_host()
  File "/home/cheh/projects/dsam/backend/venv/lib/python3.10/site-packages/django/http/request.py", line 152, in get_host
    raise DisallowedHost(msg)
django.core.exceptions.DisallowedHost: Invalid HTTP_HOST header: '0.0.0.0:8000'. You may need to add '0.0.0.0' to ALLOWED_HOSTS.
Traceback (most recent call last):
  File "/home/cheh/projects/dsam/backend/venv/lib/python3.10/site-packages/django/core/handlers/exception.py", line 56, in inner
    response = get_response(request)
  File "/home/cheh/projects/dsam/backend/venv/lib/python3.10/site-packages/django/utils/deprecation.py", line 135, in __call__
    response = self.process_request(request)
  File "/home/cheh/projects/dsam/backend/venv/lib/python3.10/site-packages/django/middleware/common.py", line 48, in process_request
    host = request.get_host()
  File "/home/cheh/projects/dsam/backend/venv/lib/python3.10/site-packages/django/http/request.py", line 152, in get_host
    raise DisallowedHost(msg)
django.core.exceptions.DisallowedHost: Invalid HTTP_HOST header: '0.0.0.0:8000'. You may need to add '0.0.0.0' to ALLOWED_HOSTS.

During handling of the above exception, another exception occurred:

Traceback (most recent call last):
  File "/home/cheh/projects/dsam/backend/venv/lib/python3.10/site-packages/django/core/handlers/exception.py", line 56, in inner
    response = get_response(request)
  File "/home/cheh/projects/dsam/backend/venv/lib/python3.10/site-packages/django/utils/deprecation.py", line 136, in __call__
    response = response or self.get_response(request)
  File "/home/cheh/projects/dsam/backend/venv/lib/python3.10/site-packages/django/core/handlers/exception.py", line 58, in inner
    response = response_for_exception(request, exc)
  File "/home/cheh/projects/dsam/backend/venv/lib/python3.10/site-packages/django/core/handlers/exception.py", line 131, in response_for_exception
    response = debug.technical_500_response(
  File "/home/cheh/projects/dsam/backend/venv/lib/python3.10/site-packages/django/views/debug.py", line 66, in technical_500_response
    html = reporter.get_traceback_html()
  File "/home/cheh/projects/dsam/backend/venv/lib/python3.10/site-packages/django/views/debug.py", line 396, in get_traceback_html
    c = Context(self.get_traceback_data(), use_l10n=False)
  File "/home/cheh/projects/dsam/backend/venv/lib/python3.10/site-packages/django/views/debug.py", line 366, in get_traceback_data
    "settings": self.filter.get_safe_settings(),
  File "/home/cheh/projects/dsam/backend/venv/lib/python3.10/site-packages/django/views/debug.py", line 150, in get_safe_settings
    settings_dict[k] = self.cleanse_setting(k, getattr(settings, k))
  File "/home/cheh/projects/dsam/backend/venv/lib/python3.10/site-packages/django/conf/__init__.py", line 101, in __getattr__
    raise ImproperlyConfigured("The SECRET_KEY setting must not be empty.")
django.core.exceptions.ImproperlyConfigured: The SECRET_KEY setting must not be empty.

During handling of the above exception, another exception occurred:

Traceback (most recent call last):
  File "/home/cheh/projects/dsam/backend/venv/lib/python3.10/site-packages/django/core/handlers/exception.py", line 56, in inner
    response = get_response(request)
  File "/home/cheh/projects/dsam/backend/venv/lib/python3.10/site-packages/django/utils/deprecation.py", line 136, in __call__
    response = response or self.get_response(request)
  File "/home/cheh/projects/dsam/backend/venv/lib/python3.10/site-packages/django/core/handlers/exception.py", line 58, in inner
    response = response_for_exception(request, exc)
  File "/home/cheh/projects/dsam/backend/venv/lib/python3.10/site-packages/django/core/handlers/exception.py", line 141, in response_for_exception
    response = handle_uncaught_exception(
  File "/home/cheh/projects/dsam/backend/venv/lib/python3.10/site-packages/django/core/handlers/exception.py", line 182, in handle_uncaught_exception
    return debug.technical_500_response(request, *exc_info)
  File "/home/cheh/projects/dsam/backend/venv/lib/python3.10/site-packages/django/views/debug.py", line 66, in technical_500_response
    html = reporter.get_traceback_html()
  File "/home/cheh/projects/dsam/backend/venv/lib/python3.10/site-packages/django/views/debug.py", line 396, in get_traceback_html
    c = Context(self.get_traceback_data(), use_l10n=False)
  File "/home/cheh/projects/dsam/backend/venv/lib/python3.10/site-packages/django/views/debug.py", line 366, in get_traceback_data
    "settings": self.filter.get_safe_settings(),
  File "/home/cheh/projects/dsam/backend/venv/lib/python3.10/site-packages/django/views/debug.py", line 150, in get_safe_settings
    settings_dict[k] = self.cleanse_setting(k, getattr(settings, k))
  File "/home/cheh/projects/dsam/backend/venv/lib/python3.10/site-packages/django/conf/__init__.py", line 101, in __getattr__
    raise ImproperlyConfigured("The SECRET_KEY setting must not be empty.")
django.core.exceptions.ImproperlyConfigured: The SECRET_KEY setting must not be empty.

During handling of the above exception, another exception occurred:

Traceback (most recent call last):
  File "/home/cheh/projects/dsam/backend/venv/lib/python3.10/site-packages/django/core/handlers/exception.py", line 56, in inner
    response = get_response(request)
  File "/home/cheh/projects/dsam/backend/venv/lib/python3.10/site-packages/django/utils/deprecation.py", line 136, in __call__
    response = response or self.get_response(request)
  File "/home/cheh/projects/dsam/backend/venv/lib/python3.10/site-packages/django/core/handlers/exception.py", line 58, in inner
    response = response_for_exception(request, exc)
  File "/home/cheh/projects/dsam/backend/venv/lib/python3.10/site-packages/django/core/handlers/exception.py", line 141, in response_for_exception
    response = handle_uncaught_exception(
  File "/home/cheh/projects/dsam/backend/venv/lib/python3.10/site-packages/django/core/handlers/exception.py", line 182, in handle_uncaught_exception
    return debug.technical_500_response(request, *exc_info)
  File "/home/cheh/projects/dsam/backend/venv/lib/python3.10/site-packages/django/views/debug.py", line 66, in technical_500_response
    html = reporter.get_traceback_html()
  File "/home/cheh/projects/dsam/backend/venv/lib/python3.10/site-packages/django/views/debug.py", line 396, in get_traceback_html
    c = Context(self.get_traceback_data(), use_l10n=False)
  File "/home/cheh/projects/dsam/backend/venv/lib/python3.10/site-packages/django/views/debug.py", line 366, in get_traceback_data
    "settings": self.filter.get_safe_settings(),
  File "/home/cheh/projects/dsam/backend/venv/lib/python3.10/site-packages/django/views/debug.py", line 150, in get_safe_settings
    settings_dict[k] = self.cleanse_setting(k, getattr(settings, k))
  File "/home/cheh/projects/dsam/backend/venv/lib/python3.10/site-packages/django/conf/__init__.py", line 101, in __getattr__
    raise ImproperlyConfigured("The SECRET_KEY setting must not be empty.")
django.core.exceptions.ImproperlyConfigured: The SECRET_KEY setting must not be empty.

During handling of the above exception, another exception occurred:

Traceback (most recent call last):
  File "/usr/lib/python3.10/wsgiref/handlers.py", line 137, in run
    self.result = application(self.environ, self.start_response)
  File "/home/cheh/projects/dsam/backend/venv/lib/python3.10/site-packages/django/contrib/staticfiles/handlers.py", line 80, in __call__
    return self.application(environ, start_response)
  File "/home/cheh/projects/dsam/backend/venv/lib/python3.10/site-packages/django/core/handlers/wsgi.py", line 131, in __call__
    response = self.get_response(request)
  File "/home/cheh/projects/dsam/backend/venv/lib/python3.10/site-packages/django/core/handlers/base.py", line 140, in get_response
    response = self._middleware_chain(request)
  File "/home/cheh/projects/dsam/backend/venv/lib/python3.10/site-packages/django/core/handlers/exception.py", line 58, in inner
    response = response_for_exception(request, exc)
  File "/home/cheh/projects/dsam/backend/venv/lib/python3.10/site-packages/django/core/handlers/exception.py", line 141, in response_for_exception
    response = handle_uncaught_exception(
  File "/home/cheh/projects/dsam/backend/venv/lib/python3.10/site-packages/django/core/handlers/exception.py", line 182, in handle_uncaught_exception
    return debug.technical_500_response(request, *exc_info)
  File "/home/cheh/projects/dsam/backend/venv/lib/python3.10/site-packages/django/views/debug.py", line 66, in technical_500_response
    html = reporter.get_traceback_html()
  File "/home/cheh/projects/dsam/backend/venv/lib/python3.10/site-packages/django/views/debug.py", line 396, in get_traceback_html
    c = Context(self.get_traceback_data(), use_l10n=False)
  File "/home/cheh/projects/dsam/backend/venv/lib/python3.10/site-packages/django/views/debug.py", line 366, in get_traceback_data
    "settings": self.filter.get_safe_settings(),
  File "/home/cheh/projects/dsam/backend/venv/lib/python3.10/site-packages/django/views/debug.py", line 150, in get_safe_settings
    settings_dict[k] = self.cleanse_setting(k, getattr(settings, k))
  File "/home/cheh/projects/dsam/backend/venv/lib/python3.10/site-packages/django/conf/__init__.py", line 101, in __getattr__
    raise ImproperlyConfigured("The SECRET_KEY setting must not be empty.")
django.core.exceptions.ImproperlyConfigured: The SECRET_KEY setting must not be empty.
[21/Mar/2023 00:04:08] "GET / HTTP/1.1" 500 59
Invalid HTTP_HOST header: '0.0.0.0:8000'. You may need to add '0.0.0.0' to ALLOWED_HOSTS.
Traceback (most recent call last):
  File "/home/cheh/projects/dsam/backend/venv/lib/python3.10/site-packages/django/core/handlers/exception.py", line 56, in inner
    response = get_response(request)
  File "/home/cheh/projects/dsam/backend/venv/lib/python3.10/site-packages/django/utils/deprecation.py", line 135, in __call__
    response = self.process_request(request)
  File "/home/cheh/projects/dsam/backend/venv/lib/python3.10/site-packages/django/middleware/common.py", line 48, in process_request
    host = request.get_host()
  File "/home/cheh/projects/dsam/backend/venv/lib/python3.10/site-packages/django/http/request.py", line 152, in get_host
    raise DisallowedHost(msg)
django.core.exceptions.DisallowedHost: Invalid HTTP_HOST header: '0.0.0.0:8000'. You may need to add '0.0.0.0' to ALLOWED_HOSTS.
Traceback (most recent call last):
  File "/home/cheh/projects/dsam/backend/venv/lib/python3.10/site-packages/django/core/handlers/exception.py", line 56, in inner
    response = get_response(request)
  File "/home/cheh/projects/dsam/backend/venv/lib/python3.10/site-packages/django/utils/deprecation.py", line 135, in __call__
    response = self.process_request(request)
  File "/home/cheh/projects/dsam/backend/venv/lib/python3.10/site-packages/django/middleware/common.py", line 48, in process_request
    host = request.get_host()
  File "/home/cheh/projects/dsam/backend/venv/lib/python3.10/site-packages/django/http/request.py", line 152, in get_host
    raise DisallowedHost(msg)
django.core.exceptions.DisallowedHost: Invalid HTTP_HOST header: '0.0.0.0:8000'. You may need to add '0.0.0.0' to ALLOWED_HOSTS.

During handling of the above exception, another exception occurred:

Traceback (most recent call last):
  File "/home/cheh/projects/dsam/backend/venv/lib/python3.10/site-packages/django/core/handlers/exception.py", line 56, in inner
    response = get_response(request)
  File "/home/cheh/projects/dsam/backend/venv/lib/python3.10/site-packages/django/utils/deprecation.py", line 136, in __call__
    response = response or self.get_response(request)
  File "/home/cheh/projects/dsam/backend/venv/lib/python3.10/site-packages/django/core/handlers/exception.py", line 58, in inner
    response = response_for_exception(request, exc)
  File "/home/cheh/projects/dsam/backend/venv/lib/python3.10/site-packages/django/core/handlers/exception.py", line 131, in response_for_exception
    response = debug.technical_500_response(
  File "/home/cheh/projects/dsam/backend/venv/lib/python3.10/site-packages/django/views/debug.py", line 66, in technical_500_response
    html = reporter.get_traceback_html()
  File "/home/cheh/projects/dsam/backend/venv/lib/python3.10/site-packages/django/views/debug.py", line 396, in get_traceback_html
    c = Context(self.get_traceback_data(), use_l10n=False)
  File "/home/cheh/projects/dsam/backend/venv/lib/python3.10/site-packages/django/views/debug.py", line 366, in get_traceback_data
    "settings": self.filter.get_safe_settings(),
  File "/home/cheh/projects/dsam/backend/venv/lib/python3.10/site-packages/django/views/debug.py", line 150, in get_safe_settings
    settings_dict[k] = self.cleanse_setting(k, getattr(settings, k))
  File "/home/cheh/projects/dsam/backend/venv/lib/python3.10/site-packages/django/conf/__init__.py", line 101, in __getattr__
    raise ImproperlyConfigured("The SECRET_KEY setting must not be empty.")
django.core.exceptions.ImproperlyConfigured: The SECRET_KEY setting must not be empty.

During handling of the above exception, another exception occurred:

Traceback (most recent call last):
  File "/home/cheh/projects/dsam/backend/venv/lib/python3.10/site-packages/django/core/handlers/exception.py", line 56, in inner
    response = get_response(request)
  File "/home/cheh/projects/dsam/backend/venv/lib/python3.10/site-packages/django/utils/deprecation.py", line 136, in __call__
    response = response or self.get_response(request)
  File "/home/cheh/projects/dsam/backend/venv/lib/python3.10/site-packages/django/core/handlers/exception.py", line 58, in inner
    response = response_for_exception(request, exc)
  File "/home/cheh/projects/dsam/backend/venv/lib/python3.10/site-packages/django/core/handlers/exception.py", line 141, in response_for_exception
    response = handle_uncaught_exception(
  File "/home/cheh/projects/dsam/backend/venv/lib/python3.10/site-packages/django/core/handlers/exception.py", line 182, in handle_uncaught_exception
    return debug.technical_500_response(request, *exc_info)
  File "/home/cheh/projects/dsam/backend/venv/lib/python3.10/site-packages/django/views/debug.py", line 66, in technical_500_response
    html = reporter.get_traceback_html()
  File "/home/cheh/projects/dsam/backend/venv/lib/python3.10/site-packages/django/views/debug.py", line 396, in get_traceback_html
    c = Context(self.get_traceback_data(), use_l10n=False)
  File "/home/cheh/projects/dsam/backend/venv/lib/python3.10/site-packages/django/views/debug.py", line 366, in get_traceback_data
    "settings": self.filter.get_safe_settings(),
  File "/home/cheh/projects/dsam/backend/venv/lib/python3.10/site-packages/django/views/debug.py", line 150, in get_safe_settings
    settings_dict[k] = self.cleanse_setting(k, getattr(settings, k))
  File "/home/cheh/projects/dsam/backend/venv/lib/python3.10/site-packages/django/conf/__init__.py", line 101, in __getattr__
    raise ImproperlyConfigured("The SECRET_KEY setting must not be empty.")
django.core.exceptions.ImproperlyConfigured: The SECRET_KEY setting must not be empty.

During handling of the above exception, another exception occurred:

Traceback (most recent call last):
  File "/home/cheh/projects/dsam/backend/venv/lib/python3.10/site-packages/django/core/handlers/exception.py", line 56, in inner
    response = get_response(request)
  File "/home/cheh/projects/dsam/backend/venv/lib/python3.10/site-packages/django/utils/deprecation.py", line 136, in __call__
    response = response or self.get_response(request)
  File "/home/cheh/projects/dsam/backend/venv/lib/python3.10/site-packages/django/core/handlers/exception.py", line 58, in inner
    response = response_for_exception(request, exc)
  File "/home/cheh/projects/dsam/backend/venv/lib/python3.10/site-packages/django/core/handlers/exception.py", line 141, in response_for_exception
    response = handle_uncaught_exception(
  File "/home/cheh/projects/dsam/backend/venv/lib/python3.10/site-packages/django/core/handlers/exception.py", line 182, in handle_uncaught_exception
    return debug.technical_500_response(request, *exc_info)
  File "/home/cheh/projects/dsam/backend/venv/lib/python3.10/site-packages/django/views/debug.py", line 66, in technical_500_response
    html = reporter.get_traceback_html()
  File "/home/cheh/projects/dsam/backend/venv/lib/python3.10/site-packages/django/views/debug.py", line 396, in get_traceback_html
    c = Context(self.get_traceback_data(), use_l10n=False)
  File "/home/cheh/projects/dsam/backend/venv/lib/python3.10/site-packages/django/views/debug.py", line 366, in get_traceback_data
    "settings": self.filter.get_safe_settings(),
  File "/home/cheh/projects/dsam/backend/venv/lib/python3.10/site-packages/django/views/debug.py", line 150, in get_safe_settings
    settings_dict[k] = self.cleanse_setting(k, getattr(settings, k))
  File "/home/cheh/projects/dsam/backend/venv/lib/python3.10/site-packages/django/conf/__init__.py", line 101, in __getattr__
    raise ImproperlyConfigured("The SECRET_KEY setting must not be empty.")
django.core.exceptions.ImproperlyConfigured: The SECRET_KEY setting must not be empty.

During handling of the above exception, another exception occurred:

Traceback (most recent call last):
  File "/usr/lib/python3.10/wsgiref/handlers.py", line 137, in run
    self.result = application(self.environ, self.start_response)
  File "/home/cheh/projects/dsam/backend/venv/lib/python3.10/site-packages/django/contrib/staticfiles/handlers.py", line 80, in __call__
    return self.application(environ, start_response)
  File "/home/cheh/projects/dsam/backend/venv/lib/python3.10/site-packages/django/core/handlers/wsgi.py", line 131, in __call__
    response = self.get_response(request)
  File "/home/cheh/projects/dsam/backend/venv/lib/python3.10/site-packages/django/core/handlers/base.py", line 140, in get_response
    response = self._middleware_chain(request)
  File "/home/cheh/projects/dsam/backend/venv/lib/python3.10/site-packages/django/core/handlers/exception.py", line 58, in inner
    response = response_for_exception(request, exc)
  File "/home/cheh/projects/dsam/backend/venv/lib/python3.10/site-packages/django/core/handlers/exception.py", line 141, in response_for_exception
    response = handle_uncaught_exception(
  File "/home/cheh/projects/dsam/backend/venv/lib/python3.10/site-packages/django/core/handlers/exception.py", line 182, in handle_uncaught_exception
    return debug.technical_500_response(request, *exc_info)
  File "/home/cheh/projects/dsam/backend/venv/lib/python3.10/site-packages/django/views/debug.py", line 66, in technical_500_response
    html = reporter.get_traceback_html()
  File "/home/cheh/projects/dsam/backend/venv/lib/python3.10/site-packages/django/views/debug.py", line 396, in get_traceback_html
    c = Context(self.get_traceback_data(), use_l10n=False)
  File "/home/cheh/projects/dsam/backend/venv/lib/python3.10/site-packages/django/views/debug.py", line 366, in get_traceback_data
    "settings": self.filter.get_safe_settings(),
  File "/home/cheh/projects/dsam/backend/venv/lib/python3.10/site-packages/django/views/debug.py", line 150, in get_safe_settings
    settings_dict[k] = self.cleanse_setting(k, getattr(settings, k))
  File "/home/cheh/projects/dsam/backend/venv/lib/python3.10/site-packages/django/conf/__init__.py", line 101, in __getattr__
    raise ImproperlyConfigured("The SECRET_KEY setting must not be empty.")
django.core.exceptions.ImproperlyConfigured: The SECRET_KEY setting must not be empty.
[21/Mar/2023 00:04:08] "GET /favicon.ico HTTP/1.1" 500 59
